Workbook
Name baganusia1: #REF!
Name Slicer_KONTINGEN: #N/A
Name Slicer_NO._KELAS: #N/A

Sheet TABEL KELAS
G1: PERHATIAN... UNTUK MENGISI DATA ATLET ADA DI SHEET OPEN, dan FESTIVAL YANG DIISI HANYA KOLOM YG BERWARNA KUNING UNTUK NO KELAS DIISI SESUAI TABEL KELAS DISAMPING.... TERIMA KASIH
A7: OPEN | C7: FESTIVAL
A8: NO KELAS | B8: KELAS | C8: NO KELAS | D8: KELAS
A9: 1 | B9: KATA PERORANGAN PRA USIA DINI PUTRA | C9: F1 | D9: KATA PERORANGAN PAUD/TK PUTRA
A10: 2 | B10: KATA PERORANGAN PRA USIA DINI PUTRI | C10: F2 | D10: KATA PERORANGAN PAUD/TK PUTRI
A11: 3 | B11: KUMITE BEBAS PRA USIA DINI PUTRA | C11: F3 | D11: KUMITE -25 KG PAUD/TK PUTRA
A12: 4 | B12: KUMITE BEBAS PRA USIA DINI PUTRI | C12: F4 | D12: KUMITE +25 KG PAUD/TK PUTRA
A13: 5 | B13: KATA BEREGU USIA DINI PUTRA | C13: F5 | D13: KUMITE -25 KG PAUD/TK PUTRI
A14: 6 | B14: KATA BEREGU USIA DINI PUTRI | C14: F6 | D14: KUMITE +25 KG PAUD/TK PUTRI
A15: 7 | B15: KATA PERORANGAN USIA DINI PUTRA | C15: F7 | D15: KATA PERORANGAN SD 1-3 PUTRA
A16: 8 | B16: KATA PERORANGAN USIA DINI PUTRI | C16: F8 | D16: KATA PERORANGAN SD 1-3 PUTRI
A17: 9 | B17: KUMITE -30 KG USIA DINI PUTRA | C17: F9 | D17: KUMITE -25 KG SD 1-3 PUTRA
A18: 10 | B18: KUMITE +30 KG USIA DINI PUTRA | C18: F10 | D18: KUMITE +25 KG SD 1-3 PUTRA
A19: 11 | B19: KUMITE -25 KG USIA DINI PUTRI | C19: F11 | D19: KUMITE -25 KG SD 1-3 PUTRI
A20: 12 | B20: KUMITE +25 KG USIA DINI PUTRI | C20: F12 | D20: KUMITE +25 KG SD 1-3 PUTRI
... A50: 42 | B50: KUMITE -63 KG KADET PUTRA | C50: F42 | D50: KUMITE + 55 KG MAHASISWA/UMUM PUTRI
A51: 43 | B51: KUMITE -70 KG KADET PUTRA
A52: 44 | B52: KUMITE +70 KG KADET PUTRA
A53: 45 | B53: KUMITE -47 KG KADET PUTRI
A54: 46 | B54: KUMITE -54 KG KADET PUTRI
A55: 47 | B55: KUMITE -61 KG KADET PUTRI
A56: 48 | B56: KUMITE +61 KG KADET PUTRI
A57: 49 | B57: KATA PERORANGAN JUNIOR PUTRA
A58: 50 | B58: KATA PERORANGAN JUNIOR PUTRI
A59: 51 | B59: KATA BEREGU JUNIOR PUTRA
A60: 52 | B60: KATA BEREGU JUNIOR PUTRI
A61: 53 | B61: KUMITE -55 KG JUNIOR PUTRA
A62: 54 | B62: KUMITE -61 KG JUNIOR PUTRA
... A100: 92 | B100: KUMITE +68 KG SENIOR PUTRI

Sheet FESTIVAL
C7: NAMA KONTINGEN | D7: : | I7: JML KELAS | J7: L | K7: P | L7: TOTAL
C8: KOTA/KAB KONTINGEN | D8: : | I8: PERORANGAN | J8: =COUNTIF(D145:D244,"L") -> 0 | K8: =COUNTIF(D145:D244,"P") -> 0 | L8: =J8+K8 -> 0
C9: NAMA MANAGER | D9: :
C10: NO. TELP/WA | D10: :
A13: FORM FESTIVAL
A14: NO. URUT | B14: NO. KELAS | C14: KELAS PERTANDINGAN | D14: LP | E14: NAMA LENGKAP | F14: TGL LAHIR | G14: KATEGORI | J14: BERAT (Kg) | K14: KONTINGEN
C15: (OTOMATIS) | E15: ( HURUF BALOK ) | F15: (MM/DD/YYYY) | I15: (OTOMATIS)
C16: =VLOOKUP(B16,$M$16:$N$144,2,FALSE) -> #N/A | G16: =DATEDIF(F16,H16,"Y") -> 126 | H16: 46387 | I16: =VLOOKUP(G16,$P$16:$Q$144,2,FALSE) -> #N/A | M16: F1 | N16: KATA PERORANGAN PAUD/TK PUTRA | O16: L | P16: 5 | Q16: PAUD/TK
C17: =VLOOKUP(B17,$M$16:$N$144,2,FALSE) -> #N/A | G17: =DATEDIF(F17,H17,"Y") -> 126 | H17: =H16 -> 46387 | I17: =VLOOKUP(G17,$P$16:$Q$144,2,FALSE) -> #N/A | M17: F2 | N17: KATA PERORANGAN PAUD/TK PUTRI | O17: P | P17: 6 | Q17: PAUD/TK
C18: =VLOOKUP(B18,$M$16:$N$144,2,FALSE) -> #N/A | G18: =DATEDIF(F18,H18,"Y") -> 126 | H18: =H17 -> 46387 | I18: =VLOOKUP(G18,$P$16:$Q$144,2,FALSE) -> #N/A | M18: F3 | N18: KUMITE -25 KG PAUD/TK PUTRA | O18: L | P18: 7 | Q18: SD/MI 1-3
C19: =VLOOKUP(B19,$M$16:$N$144,2,FALSE) -> #N/A | G19: =DATEDIF(F19,H19,"Y") -> 126 | H19: =H18 -> 46387 | I19: =VLOOKUP(G19,$P$16:$Q$144,2,FALSE) -> #N/A | M19: F4 | N19: KUMITE +25 KG PAUD/TK PUTRA | O19: L | P19: 8 | Q19: SD/MI 1-3
C20: =VLOOKUP(B20,$M$16:$N$144,2,FALSE) -> #N/A | G20: =DATEDIF(F20,H20,"Y") -> 126 | H20: =H19 -> 46387 | I20: =VLOOKUP(G20,$P$16:$Q$144,2,FALSE) -> #N/A | M20: F5 | N20: KUMITE -25 KG PAUD/TK PUTRI | O20: P | P20: 9 | Q20: SD/MI 1-3
C21: =VLOOKUP(B21,$M$16:$N$144,2,FALSE) -> #N/A | G21: =DATEDIF(F21,H21,"Y") -> 126 | H21: =H20 -> 46387 | I21: =VLOOKUP(G21,$P$16:$Q$144,2,FALSE) -> #N/A | M21: F6 | N21: KUMITE +25 KG PAUD/TK PUTRI | O21: P | P21: 10 | Q21: SD/MI 4-6
C22: =VLOOKUP(B22,$M$16:$N$144,2,FALSE) -> #N/A | G22: =DATEDIF(F22,H22,"Y") -> 126 | H22: =H21 -> 46387 | I22: =VLOOKUP(G22,$P$16:$Q$144,2,FALSE) -> #N/A | M22: F7 | N22: KATA PERORANGAN SD 1-3 PUTRA | O22: L | P22: 11 | Q22: SD/MI 4-6
C23: =VLOOKUP(B23,$M$16:$N$144,2,FALSE) -> #N/A | G23: =DATEDIF(F23,H23,"Y") -> 126 | H23: =H22 -> 46387 | I23: =VLOOKUP(G23,$P$16:$Q$144,2,FALSE) -> #N/A | M23: F8 | N23: KATA PERORANGAN SD 1-3 PUTRI | O23: P | P23: 12 | Q23: SD/MI 4-6
C24: =VLOOKUP(B24,$M$16:$N$144,2,FALSE) -> #N/A | G24: =DATEDIF(F24,H24,"Y") -> 126 | H24: =H23 -> 46387 | I24: =VLOOKUP(G24,$P$16:$Q$144,2,FALSE) -> #N/A | M24: F9 | N24: KUMITE -25 KG SD 1-3 PUTRA | O24: L | P24: 13 | Q24: SMP/MTS
C25: =VLOOKUP(B25,$M$16:$N$144,2,FALSE) -> #N/A | G25: =DATEDIF(F25,H25,"Y") -> 126 | H25: =H24 -> 46387 | I25: =VLOOKUP(G25,$P$16:$Q$144,2,FALSE) -> #N/A | M25: F10 | N25: KUMITE +25 KG SD 1-3 PUTRA | O25: L | P25: 14 | Q25: SMP/MTS
C26: =VLOOKUP(B26,$M$16:$N$144,2,FALSE) -> #N/A | G26: =DATEDIF(F26,H26,"Y") -> 126 | H26: =H25 -> 46387 | I26: =VLOOKUP(G26,$P$16:$Q$144,2,FALSE) -> #N/A | M26: F11 | N26: KUMITE -25 KG SD 1-3 PUTRI | O26: P | P26: 15 | Q26: SMP/MTS
C27: =VLOOKUP(B27,$M$16:$N$144,2,FALSE) -> #N/A | G27: =DATEDIF(F27,H27,"Y") -> 126 | H27: =H26 -> 46387 | I27: =VLOOKUP(G27,$P$16:$Q$144,2,FALSE) -> #N/A | M27: F12 | N27: KUMITE +25 KG SD 1-3 PUTRI | O27: P | P27: 16 | Q27: SMA/SMK/MA
C28: =VLOOKUP(B28,$M$16:$N$144,2,FALSE) -> #N/A | G28: =DATEDIF(F28,H28,"Y") -> 126 | H28: =H27 -> 46387 | I28: =VLOOKUP(G28,$P$16:$Q$144,2,FALSE) -> #N/A | M28: F13 | N28: KATA PERORANGAN SD 4-6 PUTRA | O28: L | P28: 17 | Q28: SMA/SMK/MA
... C41: =VLOOKUP(B41,$M$16:$N$144,2,FALSE) -> #N/A | G41: =DATEDIF(F41,H41,"Y") -> 126 | H41: =H40 -> 46387 | I41: =VLOOKUP(G41,$P$16:$Q$144,2,FALSE) -> #N/A | M41: F26 | N41: KUMITE + 40 KG SMP/MTS PUTRI | O41: P | P41: 30 | Q41: MAHASISWA/UMUM
M42: F27 | N42: KATA PERORANGAN SMA/SMK/MA PUTRA | O42: L | P42: 31 | Q42: MAHASISWA/UMUM
M43: F28 | N43: KATA PERORANGAN SMA/SMK/MA PUTRI | O43: P | P43: 32 | Q43: MAHASISWA/UMUM
M44: F29 | N44: KUMITE - 45 KG SMA/SMK/MA PUTRA | O44: L | P44: 33 | Q44: MAHASISWA/UMUM
M45: F30 | N45: KUMITE - 50 KG SMA/SMK/MA PUTRA | O45: L | P45: 34 | Q45: MAHASISWA/UMUM
M46: F31 | N46: KUMITE + 50 KG SMA/SMK/MA PUTRA | O46: L | P46: 35 | Q46: MAHASISWA/UMUM
M47: F32 | N47: KUMITE - 45 KG SMA/SMK/MA PUTRI | O47: P | P47: 36 | Q47: MAHASISWA/UMUM
M48: F33 | N48: KUMITE - 50 KG SMA/SMK/MA PUTRI | O48: P | P48: 37 | Q48: MAHASISWA/UMUM
M49: F34 | N49: KUMITE + 50 KG SMA/SMK/MA PUTRI | O49: P | P49: 38 | Q49: MAHASISWA/UMUM
M50: F35 | N50: KATA PERORANGAN MAHASISWA/UMUM PUTRA | O50: L | P50: 39 | Q50: MAHASISWA/UMUM
M51: F36 | N51: KATA PERORANGAN MAHASISWA/UMUM PUTRI | O51: P | P51: 40 | Q51: MAHASISWA/UMUM
M52: F37 | N52: KUMITE - 50 KG MAHASISWA/UMUM PUTRA | O52: L | P52: 41 | Q52: MAHASISWA/UMUM
M53: F38 | N53: KUMITE - 55 KG MAHASISWA/UMUM PUTRA | O53: L | P53: 42 | Q53: MAHASISWA/UMUM
... M57: F42 | N57: KUMITE + 55 KG MAHASISWA/UMUM PUTRI | O57: P | P57: 46 | Q57: MAHASISWA/UMUM
P58: 47 | Q58: MAHASISWA/UMUM
P59: 48 | Q59: MAHASISWA/UMUM
P60: 49 | Q60: MAHASISWA/UMUM
P61: 50 | Q61: MAHASISWA/UMUM
P62: 51 | Q62: MAHASISWA/UMUM
P63: 52 | Q63: MAHASISWA/UMUM
...

Sheet OPEN
C7: NAMA KONTINGEN | D7: : | I7: JML KELAS | J7: L | K7: P | L7: TOTAL
C8: KOTA/KAB KONTINGEN | D8: : | I8: PERORANGAN | J8: =COUNTIFS(C$145:C$244, "<>*BEREGU*", D$145:D$244, "L") -> 0 | K8: =COUNTIFS(C$145:C$244, "<>*BEREGU*", D$145:D$244, "P") -> 0 | L8: =J8+K8 -> 0
C9: NAMA MANAGER | D9: : | I9: BEREGU | J9: =COUNTIFS(C$145:C$244, "*BEREGU*", D$145:D$244, "L")/3 -> 0 | K9: =COUNTIFS(C$145:C$244, "*BEREGU*", D$145:D$244, "P")/3 -> 0 | L9: =J9+K9 -> 0
C10: NO. TELP/WA | D10: : | L10: =L8+L9 -> 0
A13: FORM OPEN
A14: NO. URUT | B14: NO. KELAS | C14: KELAS PERTANDINGAN | D14: L/P | E14: NAMA LENGKAP | F14: TGL LAHIR | G14: KATEGORI | J14: BERAT (Kg) | K14: KONTINGEN
C15: (OTOMATIS) | E15: ( HURUF BALOK ) | F15: (MM/DD/YYYY) | I15: (OTOMATIS)
C16: =VLOOKUP(B16,$M$16:$N$144,2,FALSE) -> #N/A | F16: 41825 | G16: =DATEDIF(F16,H16,"Y") -> 12 | H16: 46387 | I16: =VLOOKUP(G16,$P$16:$Q$144,2,FALSE) -> PEMULA | M16: 1 | N16: KATA PERORANGAN PRA USIA DINI PUTRA | O16: L | P16: 3 | Q16: PRA USIA DINI
C17: =VLOOKUP(B17,$M$16:$N$144,2,FALSE) -> #N/A | G17: =DATEDIF(F17,H17,"Y") -> 126 | H17: =H16 -> 46387 | I17: =VLOOKUP(G17,$P$16:$Q$144,2,FALSE) -> #N/A | M17: 2 | N17: KATA PERORANGAN PRA USIA DINI PUTRI | O17: P | P17: 4 | Q17: PRA USIA DINI
C18: =VLOOKUP(B18,$M$16:$N$144,2,FALSE) -> #N/A | G18: =DATEDIF(F18,H18,"Y") -> 126 | H18: =H17 -> 46387 | I18: =VLOOKUP(G18,$P$16:$Q$144,2,FALSE) -> #N/A | M18: 3 | N18: KUMITE BEBAS PRA USIA DINI PUTRA | O18: L | P18: 5 | Q18: PRA USIA DINI
C19: =VLOOKUP(B19,$M$16:$N$144,2,FALSE) -> #N/A | G19: =DATEDIF(F19,H19,"Y") -> 126 | H19: =H18 -> 46387 | I19: =VLOOKUP(G19,$P$16:$Q$144,2,FALSE) -> #N/A | M19: 4 | N19: KUMITE BEBAS PRA USIA DINI PUTRI | O19: P | P19: 6 | Q19: PRA USIA DINI
C20: =VLOOKUP(B20,$M$16:$N$144,2,FALSE) -> #N/A | G20: =DATEDIF(F20,H20,"Y") -> 126 | H20: =H19 -> 46387 | I20: =VLOOKUP(G20,$P$16:$Q$144,2,FALSE) -> #N/A | M20: 5 | N20: KATA BEREGU USIA DINI PUTRA | O20: L | P20: 7 | Q20: PRA USIA DINI
C21: =VLOOKUP(B21,$M$16:$N$144,2,FALSE) -> #N/A | G21: =DATEDIF(F21,H21,"Y") -> 126 | H21: =H20 -> 46387 | I21: =VLOOKUP(G21,$P$16:$Q$144,2,FALSE) -> #N/A | M21: 6 | N21: KATA BEREGU USIA DINI PUTRI | O21: P | P21: 8 | Q21: USIA DINI
C22: =VLOOKUP(B22,$M$16:$N$144,2,FALSE) -> #N/A | G22: =DATEDIF(F22,H22,"Y") -> 126 | H22: =H21 -> 46387 | I22: =VLOOKUP(G22,$P$16:$Q$144,2,FALSE) -> #N/A | M22: 7 | N22: KATA PERORANGAN USIA DINI PUTRA | O22: L | P22: 9 | Q22: USIA DINI
C23: =VLOOKUP(B23,$M$16:$N$144,2,FALSE) -> #N/A | G23: =DATEDIF(F23,H23,"Y") -> 126 | H23: =H22 -> 46387 | I23: =VLOOKUP(G23,$P$16:$Q$144,2,FALSE) -> #N/A | M23: 8 | N23: KATA PERORANGAN USIA DINI PUTRI | O23: P | P23: 10 | Q23: PRA PEMULA
C24: =VLOOKUP(B24,$M$16:$N$144,2,FALSE) -> #N/A | G24: =DATEDIF(F24,H24,"Y") -> 126 | H24: =H23 -> 46387 | I24: =VLOOKUP(G24,$P$16:$Q$144,2,FALSE) -> #N/A | M24: 9 | N24: KUMITE -30 KG USIA DINI PUTRA | O24: L | P24: 11 | Q24: PRA PEMULA
C25: =VLOOKUP(B25,$M$16:$N$144,2,FALSE) -> #N/A | G25: =DATEDIF(F25,H25,"Y") -> 126 | H25: =H24 -> 46387 | I25: =VLOOKUP(G25,$P$16:$Q$144,2,FALSE) -> #N/A | M25: 10 | N25: KUMITE +30 KG USIA DINI PUTRA | O25: L | P25: 12 | Q25: PEMULA
C26: =VLOOKUP(B26,$M$16:$N$144,2,FALSE) -> #N/A | G26: =DATEDIF(F26,H26,"Y") -> 126 | H26: =H25 -> 46387 | I26: =VLOOKUP(G26,$P$16:$Q$144,2,FALSE) -> #N/A | M26: 11 | N26: KUMITE -25 KG USIA DINI PUTRI | O26: P | P26: 13 | Q26: PEMULA
C27: =VLOOKUP(B27,$M$16:$N$144,2,FALSE) -> #N/A | G27: =DATEDIF(F27,H27,"Y") -> 126 | H27: =H26 -> 46387 | I27: =VLOOKUP(G27,$P$16:$Q$144,2,FALSE) -> #N/A | M27: 12 | N27: KUMITE +25 KG USIA DINI PUTRI | O27: P | P27: 14 | Q27: KADET
C28: =VLOOKUP(B28,$M$16:$N$144,2,FALSE) -> #N/A | G28: =DATEDIF(F28,H28,"Y") -> 126 | H28: =H27 -> 46387 | I28: =VLOOKUP(G28,$P$16:$Q$144,2,FALSE) -> #N/A | M28: 13 | N28: KATA PERORANGAN PRA PEMULA PUTRA | O28: L | P28: 15 | Q28: KADET
... C41: =VLOOKUP(B41,$M$16:$N$144,2,FALSE) -> #N/A | G41: =DATEDIF(F41,H41,"Y") -> 126 | H41: =H40 -> 46387 | I41: =VLOOKUP(G41,$P$16:$Q$144,2,FALSE) -> #N/A | M41: 26 | N41: KATA BEREGU PEMULA PUTRI | O41: P | P41: 28 | Q41: SENIOR
M42: 27 | N42: KUMITE -40 KG PEMULA PUTRA | O42: L | P42: 29 | Q42: SENIOR
M43: 28 | N43: KUMITE -45 KG PEMULA PUTRA | O43: L | P43: 30 | Q43: SENIOR
M44: 29 | N44: KUMITE -50 KG PEMULA PUTRA | O44: L | P44: 31 | Q44: SENIOR
M45: 30 | N45: KUMITE -55 KG PEMULA PUTRA | O45: L | P45: 32 | Q45: SENIOR
M46: 31 | N46: KUMITE +55 KG PEMULA PUTRA | O46: L | P46: 33 | Q46: SENIOR
M47: 32 | N47: KUMITE -40 KG PEMULA PUTRI | O47: P | P47: 34 | Q47: SENIOR
M48: 33 | N48: KUMITE -45 KG PEMULA PUTRI | O48: P | P48: 35 | Q48: SENIOR
M49: 34 | N49: KUMITE -52 KG PEMULA PUTRI | O49: P | P49: 36 | Q49: SENIOR
M50: 35 | N50: KUMITE +52 KG PEMULA PUTRI | O50: P | P50: 37 | Q50: SENIOR
M51: 36 | N51: KATA PERORANGAN KADET PUTRA | O51: L | P51: 38 | Q51: SENIOR
M52: 37 | N52: KATA PERORANGAN KADET PUTRI | O52: P | P52: 39 | Q52: SENIOR
M53: 38 | N53: KATA BEREGU KADET PUTRA | O53: L | P53: 40 | Q53: SENIOR
... M80: 65 | N80: KATA BEREGU UNDER-21 PUTRA | O80: L | P80: 67 | Q80: SENIOR
M81: 66 | N81: KATA BEREGU UNDER-21 PUTRI | O81: P
M82: 67 | N82: KUMITE -55 KG UNDER-21 PUTRA | O82: L
M83: 68 | N83: KUMITE -60 KG UNDER-21 PUTRA | O83: L
M84: 69 | N84: KUMITE -67 KG UNDER-21 PUTRA | O84: L
M85: 70 | N85: KUMITE -75 KG UNDER-21 PUTRA | O85: L
M86: 71 | N86: KUMITE -84 KG UNDER-21 PUTRA | O86: L
...

Sheet REKAP
A6: KONTINGEN : | B6: =FESTIVAL!E7 -> 0
A8: ID CARD
A9: Jumlah Atlit Putra
A10: Jumlah Atlit Putra
A11: Jumlah Official
A13: REKAP ADMINISTRASI
A14: KATEGORI | B14: PUTRA | C14: PUTRI | D14: SATUAN | E14: Jumlah
A15: Festival | B15: =FESTIVAL!J8 -> 0 | C15: =FESTIVAL!K8 -> 0 | D15: 250000 | E15: =D15*(B15+C15) -> 0
A16: Perorangan Open | B16: =OPEN!J8 -> 0 | C16: =OPEN!K8 -> 0 | D16: 225000 | E16: =D16*(B16+C16) -> 0
A17: Beregu Open | B17: =OPEN!J9 -> 0 | C17: =OPEN!K9 -> 0 | D17: 300000 | E17: =D17*(B17+C17) -> 0
A18: KONTINGEN | D18: 200000 | E18: =D18 -> 200000
A19: CASHBACK | B19: =SUM(B15:B17) -> 0 | C19: =SUM(C15:C17) -> 0 | D19: 25000 | E19: =(B19+C19)*D19 -> 0
A20: Total Keseluruhan | E20: =E15+E16+E17+E18-E19 -> 200000
